Workbook

Sheet Sayfa1
A3: SIRA NO | B3: KURUM ADI | C3: GENEL TOPLAM MUAYENE SAYISI (ACİL+POL+DİŞ+TÜMÜ) | D3: TOPLAM DİŞ MUAYENE SAYISI | E3: TOPLAM MUAYENE SAYISI (ACİL dahil Diş Hariç) | F3: KLİNİSYEN HEKİM BAŞINA DÜŞEN NÜFUS (TÜİK Son Açıklanan Antalya Nüfusuna Göre) | G3: KİŞİ BAŞI HEKİME MÜRACAAT SAYISI (Muayene Sayılarına Göre) (1000kişi başına) | H3: BAKILAN HASTA NİTELİĞİ (İstatistik amaçlı olup toplam sayılara mükerrer eklenmemesine dikkat edilmelidir.) | K3: ACİL MUAYENE SAYILARI VE ORANLARI | S3: POLİKLİNİK MUAYENE SAYILARI | W3: ACİLDE YAZILAN REÇETE SAYISI | AB3: POLİKLİNİKTE YAZILAN REÇETE SAYISI | AG3: YATAN HASTA SAYISI VE ORANI | AO3: TOPLAM TABURCU SAYISI | AP3: TOPLAM ÖLEN HASTA SAYSI | AQ3: ACİL SERVİSTE ÖLEN SAYISI | AR3: TESCİLLİ YATAK SAYISI | AS3: FİİLİ YATAK SAYISI | AT3: NİTELİKLİ YATAK SAYISI | AU3: NİTELİKLİ YATAK ORANI | AV3: HASTANENİZ TOPLAM YATILAN GÜN SAYISI | AW3: HASTANENİZ YATILAN GÜN SAYISI (YB HARİÇ) | AX3: HASTANENİZ YATAK DOLULUK ORANI (fiili yatak sayısına göre YB dahil) | AY3: HASTANENİZ YATAK DOLULUK ORANI (fiili yatak sayısına göre YB hariç) | AZ3: BİR HASTANIN ORTALAMA KALIŞ GÜNÜ | BA3: DEVİR ARALIĞI (Gün) | BB3: YATAK DEVİR HIZI (Hasta) | BC3: DAHİLİ BRANŞLARA AİT SERVİS YATAK SAYISI | BD3: DAHİLİ BRANŞLARA AİT SERVİS YATAK DOLULUK ORANI | BE3: CERRAHİ BRANŞLARA AİT SERVİS YATAK SAYISI | BF3: CERRAHİ BRANŞLARA AİT SERVİS YATAK DOLULUK ORANI | BG3: KLİN.UZMAN HEKİM BAŞ.DÜŞEN GÜNLÜK MUA.SAY.(Acil ve Diş Hariç) | BH3: KLİNİSYEN UZMAN HEKİM SAYISI | BI3: KLİNİSYEN OLMAYAN UZMAN HEKİM SAYISI | BJ3: TOPLAM UZMAN HEKİM SAYISI | BK3: ASİSTAN HEKİM SAYISI | BL3: PRATİSYEN HEKİM SAYISI | BM3: GENEL TOPLAM HEKİM SAYISI | BN3: DİŞ HEKİMİ SAYISI (Uzman+Normal) | BO3: ECZACI SAYISI | BP3: HEMŞİRE SAYISI | BQ3: EBE SAYISI | BR3: DİĞER SAĞLIK PERSONELİ SAYISI | BS3: DİĞER PERSONEL SAYISI | BT3: DAHİLİ BRANŞ KLİN.UZMAN HEKİM BAŞ.DÜŞEN GÜNLÜK MUA.SAY.(Acil ve Diş Hariç) | BU3: DAHİLİ BRANŞ KLİNİSYEN UZMAN SAYISI | BV3: CERRAHİ BRANŞ KLİN.UZMAN HEKİM BAŞ.DÜŞEN GÜNLÜK MUA.SAY.(Acil ve Diş Hariç) | BW3: CERRAHİ BRANŞ KLİNİSYEN UZMAN SAYISI | BX3: MESAİ İÇİ AMELİYAT SAYISI | CG3: MESAİ DIŞI AMELİYAT SAYISI | CP3: GENEL TOPLAM AMELİYAT SAYISI (MESAİ İÇİ+DIŞI)(TÜM GRUPLAR) | CQ3: TOPLAM ABC AMELİYAT SAYISI (MESAİ İÇİ+DIŞI)(ABC) | CR3: MESAİ DIŞI ABC AMELİYAT ORANI (Toplam ameliyet sayısı içindeki) | CS3: BÜYÜK VE ORTA (A,B,C,) AMELİYAT ORANI (%) (Toplam Ameliyat Sayısı İçindeki) | CT3: AMELİYAT MASASI BAŞINA DÜŞEN AMELİYAT SAYISI (GÜNLÜK) (A-B-C Ameliyatlar için) | CU3: CERR.HEK.BAŞ.DÜŞEN AYLIK BÜYÜK VE ORTA (A,B,C) AMEL.SAYISI | CV3: AMELİYAT MASA SAYISI TOPLAM | CW3: AMELİYAT MASA SAYISI AKTİF | CX3: KARDİYOLOJİ UZMAN SAYISI | CY3: KVC CERRAH SAYISI | CZ3: ANJİYOGRAFİ CİHAZ SAYISI | DA3: ANJİYOGRAFİ CİHAZ BAŞINA DÜŞEN VAKA SAYISI | DB3: KORONER ANJİYO SAYISI | DC3: STENT/PTCA KORONER GİRİŞİM YAPILAN HASTA SAYISI | DD3: BY-PASS KARARI VERİLEN HASTA SAYISI | DE3: BY-PASS YAPILAN HASTA SAYISI | DF3: TOPLAM DOĞUM SAYISI | DG3: TOPLAM NORMAL DOĞUM SAYISI | DH3: NORMAL DOĞUM ORANI | DI3: TOPLAM SEZARYEN DOĞUM SAYISI | DJ3: SEZARYEN ORANI | DK3: PRİMER SEZARYEN DOĞUM SAYISI | DL3: PRİMER SEZARYEN ORANI | DM3: MESAİ DIŞI PRİMER SEZERYAN SAYISI | DN3: MESAİ DIŞI PRİMER SEZARYEN ORANI | DO3: MÜDAHALELİ DOĞUM SAYISI | DP3: TOPLAM YOĞUN BAKIM YATAK SAYISI | DQ3: TOPLAM YOĞUN BAKIM DOLUUK ORANI | DR3: TOPLAM VENTİLATÖR SAYISI AKTİF | DS3: TOPLAM VENTİLATÖR SAYISI STANDART | DT3: YB de Kullanılan Diyaliz Cihaz Sayısı | DU3: ERİŞKİN YOĞUN BAKIMDA 1 AYDAN UZUN YATAN SAYISI (ANLIK) | DV3: ÇOCUK YOĞUN BAKIMDA 1 AYDAN UZUN YATAN SAYISI (ANLIK) | DW3: YENİDOĞAN YOĞUN BAKIMDA 1 AYDAN UZUN YATAN SAYISI (ANLIK) | DX3: ERİŞKİN YB YATAK SAYISI | EB3: ERİŞKİN YB YATAN HASTA SAYISI (*) | EF3: ERİŞKİN YB YATILAN GÜN SAYISI | EJ3: ERİŞKİN YOĞUN BAKIM YATAK DOLULUK ORANI | EN3: ERİŞKİN YB VENTİLATÖR SAYISI | ES3: ERİŞKİN YB VENTİLATÖR GÜN SAYISI | EW3: ERİŞKİN YB VENTİLATÖR DOLULUK ORANI | FA3: ÇOCUK YB YATAK SAYISI | FB3: ÇOCUK YB YATAN HASTA SAYISI | FC3: ÇOCUK YB YATILAN GÜN SAYISI | FD3: ÇOCUK YOĞUN BAKIM YATAK DOLULUK ORANI | FE3: ÇOCUK YB VENTİLATÖR SAYISI AKTİF | FF3: ÇOCUK YB VENTİLATÖR SAYISI STANDART | FG3: ÇOCUK YB VENTİLATÖR GÜN SAYISI | FH3: ÇOCUK YB VENTİLATÖR DOLULUK ORANI | FI3: YENİDOĞAN YB YATAK SAYISI | FN3: YENİDOĞAN YB YATAN HASTA SAYISI (*) | FS3: YENİDOĞAN YB YATILAN GÜN SAYISI | FX3: YENİDOĞAN YOĞUN BAKIM YATAK DOLULUK ORANI | GC3: YENİDOĞAN YB VENTİLATÖR SAYISI | GJ3: YENİDOĞAN YB VENTİLATÖR GÜN SAYISI | GO3: YENİDOĞAN YB VENTİLATÖR DOLULUK ORANI | GT3: BT | GY3: MR | HD3: KEMİK DANSİTOMETRİ | HI3: MAMOGRAFİ | HN3: EKO | HS3: EEG | HX3: EMG | IC3: USG | IH3: PET/CT | IM3: SPECT/CT | IR3: LİNEER HIZLANDIRICI | IU3: GAMA KNİFE | IX3: EVDE SAĞLIK KAPSAMINDA SON AY TAKİP EDİLEN HASTA SAYISI | IY3: EVDE SAĞLIK KAPSAMINDA SON AY ZİYARET EDİLEN HASTA SAYISI | IZ3: PDC(Personel dağılım cetveli) DOLULUK ORANI | JA3: PALYATİF BAKIM HİZMETLERİ HASTANE ROLÜ | JB3: PALYATİF BAKIM TESCİLLİ YATAK SAYISI | JC3: PALYATİF BAKIM FİİİLİ YATAK SAYISI | JD3: PALYATİF BAKIM TESCİLLİ YATAK DOLULUK ORANI (%) | JE3: PALYATİF BAKIM FİİLİ YATAK DOLULUK ORANI(%) | JF3: PALYATİF BAKIM ORTALAMA KALIŞ GÜN SAYISI
H4: SGK KAPSAMINDA BAKILAN MUAYENE SAYISI | I4: SGK DIŞI BAKILAN HASTA MUAYENE SAYISI | J4: YABANCI HASTA MUAYENE SAYISI | K4: YEŞİL ALAN MUAYENE SAYISI | L4: YEŞİL ALAN MUAYENE ORANI | M4: SARI ALAN MUAYENE SAYISI | N4: SARI ALAN MUAYENE ORANI | O4: KIRMIZI ALAN MUAYENE SAYISI | P4: KIRMIZI ALAN MUAYENE ORANI | Q4: TOPLAM ACİL MUAYENE SAYISI | R4: TOPLAM ACİL MUAYENE ORANI (Toplam muayeneler içinde acil muayenelerin oranı) | S4: DAHİLİ | T4: CERRAHİ | U4: TOPLAM POLİKLİNİK MUAYENE SAYISI | V4: POLİKLİNİK ODA SAYISI | W4: E-REÇETE | X4: E-REÇETE ORANI | Y4: MANUEL | Z4: MANUEL ORANI | AA4: TOPLAM ACİL REÇETE SAYISI | AB4: E-REÇETE | AC4: E-REÇETE ORANI | AD4: MANUEL | AE4: MANUEL ORANI | AF4: TOPLAM POLİKLİNİK REÇETE SAYISI | AG4: TOPLAM ACİLDEN YATAN HASTA SAYIS | AH4: ACİLDEN HASTA YATIŞ ORANI | AI4: TOPLAM POLİKLİNİKTEN YATAN HASTA SAYIS | AJ4: POLİKLİNİKTEN HASTA YATIŞ ORANI | AK4: TOPLAM YATAN HASTA SAYISI | AL4: GENEL HASTA YATIŞ ORANI | AM4: ACİLDEN YATAN HASTA ORANI | AN4: POLİKLİNİKTEN YATAN HASTA ORANI | BX4: A | BY4: B | BZ4: C | CA4: D | CB4: E | CC4: D GRUBU GÜNÜBİRLİK AMELİYAT SAYISI | CD4: E GRUBU GÜNÜBİRLİK AMELİYAT SAYISI | CE4: DİĞER GÜNÜBİRLİK AMELİYAT SAYISI (ABC günübirliği ifade eder) | CF4: TOPLAM MESAİ İÇİ AMELİYAT SAYISI (bu alana A, B, C,D,E dahil tüm ameliyatlar yazılacak) | CG4: A | CH4: B | CI4: C | CJ4: D | CK4: E | CL4: D GRUBU GÜNÜBİRLİK AMELİYAT SAYISI | CM4: E GRUBU GÜNÜBİRLİK AMELİYAT SAYISI | CN4: DİĞER GÜNÜBİRLİK AMELİYAT SAYISI (ABC günübirliği ifade eder) | CO4: TOPLAM MESAİ DIŞI AMELİYAT SAYISI (bu alana A, B, C,D,E dahil tüm ameliyatlar yazılacak) | DX4: 1. BASAMAK | DY4: 2. BASAMAK | DZ4: 3. BASAMAK | EA4: TOPLAM ERİŞKİN YB YATAK SAYISI | EB4: 1. BASAMAK | EC4: 2. BASAMAK | ED4: 3. BASAMAK | EE4: ERİŞKİN YB TÜM BASAMAKLAR TOPLAM YATAN HASTA SAYISI | EF4: 1. BASAMAK | EG4: 2. BASAMAK | EH4: 3. BASAMAK | EI4: ERİŞKİN YB TÜM BASAMAKLAR TOPLAM YATILAN GÜN SAYISI | EJ4: ERİŞKİN YB TÜM BASAMAKLAR GENEL YATAK DOLULUK ORANI | EK4: ERİŞKİN YB 1.BASAMAK YATAK DOLULUK ORANI | EL4: ERİŞKİN YB 2.BASAMAK YATAK DOLULUK ORANI | EM4: ERİŞKİN YB 3.BASAMAK YATAK DOLULUK ORANI | EN4: 1. BASAMAK | EO4: 2. BASAMAK | EP4: 3. BASAMAK | EQ4: TOPLAM VENT SAYISI AKTİF | ER4: TOPLAM VENT SAYISI STANDART | ES4: 1. BASAMAK | ET4: 2. BASAMAK | EU4: 3. BASAMAK | EV4: ERİŞKİN YB TÜM BASAMAKLAR TOPLAM VENTİLATÖR GÜN SAYISI | EW4: 1. BASAMAK | EX4: 2. BASAMAK | EY4: 3. BASAMAK | EZ4: ERİŞKİN YB TÜM BASAMAKLAR TOPLAM VENTİLATÖR DOLULUK ORANI | FA4: 3. BASAMAK | FB4: 3. BASAMAK | FC4: 3. BASAMAK | FD4: 3. BASAMAK | FE4: 3. BASAMAK | FF4: 3. BASAMAK | FG4: 3.BASAMAK | FH4: 3.BASAMAK | FI4: 1. BASAMAK | FJ4: 2. BASAMAK | FK4: 3. BASAMAK | FL4: 4.BASAMAK 4a | FM4: YOPLAM YENİDOĞAN YB YATAK SAYISI | FN4: 1. BASAMAK | FO4: 2. BASAMAK | FP4: 3. BASAMAK | FQ4: 4.BASAMAK 4a | FR4: YENİDOĞAN YB TÜM BASAMAKLAR TOPLAM YATAN HASTA SAYISI | FS4: 1. BASAMAK | FT4: 2. BASAMAK | FU4: 3. BASAMAK | FV4: 4.BASAMAK 4a | FW4: YENİDOĞAN YB TÜM BASAMAKLAR TOPLAM YATILAN GÜN SAYISI | FX4: 1. BASAMAK | FY4: 2. BASAMAK | FZ4: 3. BASAMAK | GA4: 4.BASAMAK 4a | GB4: YENİDOĞAN YB TÜM BASAMAKLAR GENEL YATAK DOLULUK ORANI | GC4: 1. BASAMAK | GD4: 2. BASAMAK | GE4: 3. BASAMAK | GF4: 4.BASAMAK 4a | GG4: TRANSPORT VENTİLATÖR SAYISI | GH4: TOPLAM VENT. SAYISI AKTİF | GI4: TOPLAM VENT. SAYISI STANDART | GJ4: 1. BASAMAK | GK4: 2. BASAMAK | GL4: 3. BASAMAK | GM4: 4.BASAMAK 4a | GN4: YENİDOĞAN YB TÜM BASAMAKLAR TOPLAM VENTİLATÖR GÜN SAYISI | GO4: 1. BASAMAK | GP4: 2. BASAMAK | GQ4: 3. BASAMAK | GR4: 4.BASAMAK 4a | GS4: YENİDOĞAN YB TÜM BASAMAKLAR TOPLAM VENTİLATÖR DOLULUK ORANI | GT4: CİHAZ SAYISI (Hizmet alımı dahil) | GU4: ÇEKİM SAYISI (HİZMET ALIMI DAHİL) | GV4: EN UZUN RANDEVU SÜRESİ | GW4: ***HİZMET ALIMI İLE YAPILAN ÇEKİM SAYISI | GX4: BT İÇİN HER 1000 MUAYENE İÇİN İSTENİLEN TETKİK SAYISI | GY4: CİHAZ SAYISI (Hizmet alımı dahil) | GZ4: ÇEKİM SAYISI (HİZMET ALIMI DAHİL) | HA4: EN UZUN RANDEVU SÜRESİ | HB4: ***HİZMET ALIMI İLE YAPILAN ÇEKİM SAYISI | HC4: MR İÇİN HER 1000 MUAYENE İÇİN İSTENİLEN TETKİK SAYISI | HD4: CİHAZ SAYISI (Hizmet alımı dahil) | HE4: ÇEKİM SAYISI (HİZMET ALIMI DAHİL) | HF4: EN UZUN RANDEVU SÜRESİ | HG4: ***HİZMET ALIMI İLE YAPILAN ÇEKİM SAYISI | HH4: KEMİK DANS. İÇİN HER 1000 MUAYENE İÇİN İSTENİLEN TETKİK SAYISI | HI4: CİHAZ SAYISI | HJ4: ÇEKİM SAYISI (HİZMET ALIMI DAHİL) | HK4: EN UZUN RANDEVU SÜRESİ | HL4: ***HİZMET ALIMI İLE YAPILAN ÇEKİM SAYISI | HM4: MAMOGRAFİ ÇEKİM SAYISI( HER 1000 MUAYENE İÇİN İSTENİLEN TETKİK SAYISI | HN4: CİHAZ SAYISI | HO4: ÇEKİM SAYISI (HİZMET ALIMI DAHİL) | HP4: EN UZUN RANDEVU SÜRESİ | HQ4: ***HİZMET ALIMI İLE YAPILAN ÇEKİM SAYISI | HR4: EKO ÇEKİM SAYISI( HER 1000 MUAYENE İÇİN İSTENİLEN TETKİK SAYISI) | HS4: CİHAZ SAYISI | HT4: ÇEKİM SAYISI (HİZMET ALIMI DAHİL) | HU4: EN UZUN RANDEVU SÜRESİ | HV4: ***HİZMET ALIMI İLE YAPILAN ÇEKİM SAYISI | HW4: EEG ÇEKİM SAYISI( HER 1000 MUAYENE İÇİN İSTENİLEN TETKİK SAYISI) | HX4: CİHAZ SAYISI | HY4: ÇEKİM SAYISI (HİZMET ALIMI DAHİL) | HZ4: EN UZUN RANDEVU SÜRESİ | IA4: ***HİZMET ALIMI İLE YAPILAN ÇEKİM SAYISI | IB4: EMG ÇEKİM SAYISI( HER 1000 MUAYENE İÇİN İSTENİLEN TETKİK SAYISI) | IC4: USG CİHAZ SAYISI DOPPLER DAHİL | ID4: ÇEKİM SAYISI (HİZMET ALIMI DAHİL) | IE4: EN UZUN RANDEVU SÜRESİ | IF4: ***HİZMET ALIMI İLE YAPILAN ÇEKİM SAYISI | IG4: USG ÇEKİM SAYISI( HER 1000 MUAYENE İÇİN İSTENİLEN TETKİK SAYISI) | IH4: CİHAZ SAYISI | II4: ÇEKİM SAYISI (HİZMET ALIMI DAHİL) | IJ4: EN UZUN RANDEVU SÜRESİ | IK4: ***HİZMET ALIMI İLE YAPILAN ÇEKİM SAYISI | IL4: PET/CT ÇEKİM SAYISI( HER 1000 MUAYENE İÇİN İSTENİLEN TETKİK SAYISI) | IM4: CİHAZ SAYISI | IN4: ÇEKİM SAYISI (HİZMET ALIMI DAHİL) | IO4: EN UZUN RANDEVU SÜRESİ | IP4: ***HİZMET ALIMI İLE YAPILAN ÇEKİM SAYISI | IQ4: SPECT/CT ÇEKİM SAYISI( HER 1000 MUAYENE İÇİN İSTENİLEN TETKİK SAYISI) | IR4: CİHAZ SAYISI | IS4: İŞLEM SAYISI | IT4: EN UZUN RANDEVU SÜRESİ | IU4: CİHAZ SAYISI | IV4: İŞLEM SAYISI | IW4: EN UZUN RANDEVU SÜRESİ
G5: =+E5*1000/2777677 -> 0 | X5: =+W5/AA5 -> #DIV/0! | AC5: =+AB5/AF5 -> #DIV/0! | AH5: =AG5/Q5 -> #DIV/0! | AJ5: =+AI5/U5 -> #DIV/0! | AL5: =AK5/(Q5+U5) -> #DIV/0! | AM5: =+AG5/AK5 -> #DIV/0! | AN5: =+AI5/AK5 -> #DIV/0! | AU5: =+AT5/AR5 -> #DIV/0! | AX5: =(AV5*100)/(AS5*Veri!$B$4) -> #DIV/0! | AY5: =(AV5-(EI5+FW5+FC5))/((AS5-(DP5))*Veri!$B$4) -> #DIV/0! | AZ5: =AV5/(AO5+AP5) -> #DIV/0! | BA5: =(AS5*Veri!$B$4-AV5)/(AO5+AP5) -> #DIV/0! | BB5: =(AO5+AP5)/AS5 -> #DIV/0! | BD5: =(Veri!$B$6*100)/(BC5*Veri!$B$4) -> #DIV/0! | BF5: =(Veri!$B$7*100)/(BE5*Veri!$B$4) -> #DIV/0! | BG5: =(S5+T5)/BH5 -> #DIV/0! | BT5: =S5/BU5 -> #DIV/0! | BV5: =T5/BW5 -> #DIV/0! | CP5: =+CO5+CF5 -> 0 | CQ5: =+BX5+BY5+BZ5+CG5+CH5+CI5 -> 0 | CR5: =(CG5+CH5+CI5)/CP5 -> #DIV/0! | CS5: =(CQ5)/CP5 -> #DIV/0! | CT5: =+CQ5/(CW5*365) -> #DIV/0! | CU5: =(CQ5*30)/(BW5*Veri!$B$4) -> #DIV/0! | DJ5: =DI5/DF5 -> #DIV/0! | DL5: =(DK5/(DF5-0)) -> #DIV/0! | DN5: =DM5/DK5 -> #DIV/0! | DQ5: =(EI5+FC5+FW5)*100/(DP5*Veri!$B$4) -> #DIV/0! | EA5: =SUM(DX5:DZ5) -> 0 | EE5: =SUM(EB5:ED5) -> 0 | EI5: =SUM(EF5:EH5) -> 0 | ER5: =SUM(EN5:EP5) -> 0 | EV5: =SUM(ES5:EU5) -> 0 | EW5: =ES5/(EN5*Veri!$B$4) -> #DIV/0! | EX5: =ET5/(EO5*Veri!$B$4) -> #DIV/0! | EY5: =EU5/(EP5*Veri!$B$4) -> #DIV/0! | EZ5: =EV5/(ER5*Veri!$B$4) -> #DIV/0! | FD5: =FC5/(FA5*Veri!$B$4) -> #DIV/0! | FH5: =FG5/(FF5*Veri!$B$4) -> #DIV/0! | FM5: =SUM(FI5:FL5) -> 0 | FR5: =SUM(FN5:FQ5) -> 0 | FX5: =+FS5/(FI5*Veri!$B$4) -> #DIV/0! | FY5: =+FT5/(FJ5*Veri!$B$4) -> #DIV/0! | FZ5: =+FU5/(FK5*Veri!$B$4) -> #DIV/0! | GA5: =+FV5/(FL5*Veri!$B$4) -> #DIV/0! | GB5: =+FW5/(FM5*Veri!$B$4) -> #DIV/0! | GI5: =SUM(GC5:GG5) -> 0 | GN5: =SUM(GJ5:GM5) -> 0 | GO5: =+GJ5/(GC5*Veri!$B$4) -> #DIV/0! | GP5: =+GK5/(GD5*Veri!$B$4) -> #DIV/0! | GQ5: =+GL5/(GE5*Veri!$B$4) -> #DIV/0! | GR5: =+GM5/(GF5*Veri!$B$4) -> #DIV/0! | GS5: =+GN5/(GI5*Veri!$B$4) -> #DIV/0! | GW5: 0 | GX5: =GU5/$C$5 -> #DIV/0! | HB5: 0 | HC5: =GZ5/$C$5 -> #DIV/0! | HG5: 0 | HH5: =HE5/$C$5 -> #DIV/0! | HL5: 0 | HM5: =HJ5/$C$5 -> #DIV/0! | HQ5: 0 | HR5: =HO5/$C$5 -> #DIV/0! | HV5: 0 | HW5: =HT5/$C$5 -> #DIV/0! | IA5: 0 | IB5: =HY5/$C$5 -> #DIV/0! | IF5: 0 | IG5: =ID5/$C$5 -> #DIV/0! | IK5: 0 | IL5: =II5/$C$5 -> #DIV/0! | IP5: 0 | IQ5: =IN5/$C$5 -> #DIV/0!
C6: Muayene Sayısı; bu alana hastaların ayaktan muayene, tetkik, teşhis ve tedavi hizmetlerinin yapılması amacı ile kurumunuza yapılan başvuru sayıları yazılacaktır. | D6: Toplam Diş Muayene Sayısı: Ağız Diş Hizmetleri tüm muayene sayılarını ifade eder. Kurumunuzda Ağız Diş Hizmetleri mevcut değilse “0” yazılmalıdır. | E6: Toplam Muayene Sayısı (Acil dahil Diş hariç): Sadece polikliniklerde verilen muayeneleri ifade eder. Toplam Poliklinik Muayene Sayısı ve Toplam Acil Muayene sayısının toplamına eşit olması gerekmektedir. | F6: Klinisyen Hekim Başına Düşen Nüfus: TÜİK Son Açıklanan Antalya Nüfusuna Göre bir klinisyen hekime düşen nüfus dilimini ifade eder. [ (TÜİK’in resmi olarak son açıklanan Antalya Nüfusu) / (Klinisyen Hekim (Prof,Doç,Dr.Öğr.Üy.Öğr.Gör.Uzman,Ast,Prt.) Sayısı) ] | G6: Klinisyen Hekim: Ayaktan veya yataklı hizmet birimlerinde hastaya doğrudan temas eden hasta bakan tanı koyan poliklinik hizmeti veren hekimleri ifade eder. Temel tıp bilimleri branşları, laboratuvar hizmetleri ve yönetici kadrosu bu sayının dışındadır. | H6: Bakılan Hasta Niteliği: SGK kapsamında, SGK kapsamı dışında bakılan hasta muayene sayıları ve Yabancı Hasta muayene sayıları istatistik amaçlı istenmekte olup bu sayıların toplamından muayene sayıları karşılaştırma veya teyit işlemi yapılmamalıdır. Toplam Muayene sayılarına mükerrer olarak eklenmemelidir | K6: Toplam Acil Muayene Sayısı: Acil Servis’te renk kodlarına göre ayrılmış olan tüm alanlarda verilen hizmete dair muayene sayılarını ifade eder. Alanlara ayrılmış şekilde ayrıca istenmektedir. Yeşil Alan, Sarı Alan ve Kırmızı Alan muayane sayıları Toplamı Toplam Acil Muayene Sayısı’na eşit olmalıdır | S6: Toplam Poliklinik Muayene Sayısı: Dahili veya Cerrahi Branşlara ait tüm polikliniklerde verilen hizmete dair muayene sayılarını ifade eder. Dahili ve Cerrahi muayene sayıları Toplam Muayene Sayısına eşit olmalıdır. | W6: Poliklinikte ve Acil Serviste Yazılan E- Reçete ve Manuel Reçete Sayıları ile E reçete ve Manuel Reçete Oranları ayrı ayrı tabloya yazılmalı ve bu sayılar tutarlı olmalıdır. | AG6: “Yatan Hasta Sayısı” alanına; yatışı yapılan hastalar yazılacak olup; günübirlik hastalar bu alana dâhil edilmeyecektir. | AH6: Acilden Hasta Yatış Oranı: Acilden Yatan Hasta Sayısı/Toplam Acil Muayene Sayısı | AI6: Yatan Hasta Sayısı: Belirtilen dönem içinde yatışı yapılan hastalar yazılacak olup günübirlik hastalar bu alana dâhil edilmemelidir. Ayrıca geçmiş aydan taburcu olmamış olan yatan hastalar bir sonraki ayın yatan hasta sayısı alanına dahil edilmemelidir. | AJ6: Poliklinikten Hasta Yatış Oranı: Poliklinikten Yatan Hasta Sayısı/ Toplam Poliklinik Muayene Sayısı | AL6: Genel Hasta Yatış Oranı: Toplam Yatan Hasta Sayısı / Toplam Muayene Sayısı (Acil+Pol) | AM6: Acilden Yatan Hasta Oranı: Acilden Yatan Hasta Sayısı / Toplam Yatan Hasta Sayısı | AN6: Poliklinikten Yatan Hasta Oranı: Poliklinikten Yatan Hasta Sayısı/ Toplam Yatan Hasta Sayısı | AO6: Toplam Taburcu Sayısı: Şifa haliyle, kendi isteği ile hastaneden ayrılan veya başka hastanelere sevk edilen hastaların toplamı yazılmalıdır. Hastane içinde başka servise gönderilen hastalar bu alana yazılmamalıdır. Ayrıca günübirlik hasta olup çıkış işlemi yapılan hastalar bu alana kesinlikle eklenmemelidir. Servisten yoğun bakıma nakil giden hasta, servisteki taburcu alanında kesinlikle gösterilmemelidir. | AQ6: Acil Serviste Ölen Sayısı: Hastanenin acil servisine canlı olarak gelip her türlü müdahalelerden sonra acilde ölümü gerçekleşen ayrıca acil servise ölü olarak girişi yapılan müdahale sonrasında yaşama dönen ve bir süre sonra tekrar ex olanların sayısı yazılmalıdır. Veri girişi yapılırken acildeki ölümlerin içine EX Duhuller dahil edilmeyecektir. | AR6: Tescilli Yatak Sayısı: Kuruluşun ruhsatında kayıtlı ve Sağlık Bakanlığınca tescillenmiş yatak sayıları yazılmalıdır. | AS6: Fiili Yatak Sayısı: Belirli bir tarihte veya dönemde fiilen hizmet sunumunda kullanılan, hasta kabulüne açık ve faal olan yatakların toplamı yazılmalıdır. | AU6: Nitelikli Yatak Oranı: Kurumun toplam yatak sayısı içinde WC’li ve duşlu, 1 ve 2 yataklı odalarda bulunan yatak sayısının oranını ifade etmektedir (Nitelikli Yatak Sayısı/ Tescilli Yatak Sayısı) | AX6: Hastaneniz Yatak Doluluk Oranı (YB Dahil): (Yatılan Gün Sayısı x 100) / (Fiili Yatak sayısı x belirtilen zaman dilimindeki takvim günü) | AY6: Hastaneniz Yatak Doluluk Oranı (YB Hariç): [(Yatılan Gün Sayısı-YB yatılan gün sayısı) x 100] / [(Fiili Yatak sayısı-YB fiili yatak sayısı) x belirtilen zaman dilimindeki takvim günü] | AZ6: Ortalama Kalış Günü: Bir hastanın hastanede kaldığı ortalama gün sayısını göstermektedir. (Yatılan Gün Sayısı) / (Taburcu + Ölen Kişi Sayısı) şeklinde hesaplanır. | BA6: Yatak Devir Aralığı: Bir hasta yatağının kaç gün boş kaldığını göstermektedir. (Yatak Sayısı x belirtilen zaman dilimindeki takvim günü – Yatılan Gün Sayısı) / (Taburcu + Ölen Kişi Sayısı) şeklinde hesaplanır. | BB6: Yatak Devir Hızı: Bir yatağın belirtilen zaman diliminde kaç hasta tarafından kullanıldığını göstermektedir. (Taburcu + Ölen Kişi Sayısı) / (Fiili Yatak Sayısı) şeklinde hesaplanır. | BD6: Dahili Branşlara Ait Servis Yatak Doluluk Oranı: (Dah Ser.Yatılan Gün Sayısı x 100) / (Dah. Ser. Fiili Yatak sayısı x belirtilen zaman dilimindeki takvim günü) | BF6: Cerrahi Branşlara Ait Servis Yatak Doluluk Oranı: (Cer. Ser.Yatılan Gün Sayısı x 100) / (Cer. Ser. Fiili Yatak sayısı x belirtilen zaman dilimindeki takvim günü) | BG6: Klinisyen Uzman Hekim Başına Düşen Günlük Muayene Sayısı(Acil ve Diş Hariç): Toplam Poliklinik Sayısı(dahili+cerrahi)/ Toplam Klinisyen Uzman Hekim Sayısı | BH6: Klinisyen Uzman Hekim Sayısı: Prof,Doç,Dr.Öğr.Üy.Öğr.Gör.Uzman unvanına sahip Ayaktan veya yataklı hizmet birimlerinde hastaya doğrudan temas eden hasta bakan tanı koyan poliklinik hizmeti veren hekimleri ifade eder. | BR6: Diğer Sağlık Personeli Sayısı: Ek2 de yer alan Sağlık Meslek Mensuplarının İş ve Görev Tanımları başlıklı tabloda yer alan meslekleri icra eden kişileri ifade eder. | BS6: Diğer Personel Sayısı: Ek2 ‘ de Yer Alan Diğer Meslek Mensuplarının Sağlık Himzetlerinde İş ve Görev Tanımları başlıklı tabloda yer alan ve belirtilen tablolar dışındaki tüm meslek gruplarını ifade eder. | BT6: Dahili Klinisyen Uzman Hekim Başına Düşen Günlük Muayene Sayısı(Acil ve Diş Hariç): Toplam Dahili Branş Poliklinik Sayısı / Toplam Dahili Branş Klinisyen Uzman Hekim Sayısı | BV6: Cerrahi Klinisyen Uzman Hekim Başına Düşen Günlük Muayene Sayısı(Acil ve Diş Hariç): Toplam Cerrahi Branş Poliklinik Sayısı / Toplam Cerrahi Branş Klinisyen Uzman Hekim Sayısı | BX6: AMELİYATHANE HİZMETLERİ VERİLERİ | CC6: Günübirlik Ameliyat Sayısı: Kullanılan Hastane bilgi sisteminde tedavi türü “Günübirlik” (G) olarak seçilen 1 tam gece yatış yapılmadan taburcu olan hastalara uygulanan ameliyat sayısı yazılmalıdır. Günübirlik yapılan ameliyatlar “D, E Grubu Günübirlik Ameliyat Sayısı” ile “Diğer Günübirlik (A+B+C) Ameliyat Sayısı” alanlarına girilmeli, diğer ameliyat grupları alanına girilmemelidir. | CR6: Mesai Dışı ABC Ameliyat Oranı: Mesai Dışı ABC Ameliyat Sayısı/ Toplam Ameliyat Sayısı | CS6: ABC Ameliyat Oranı: Toplam ABC Ameliyat Sayısı/ Toplam Ameliyat Sayısı | CT6: Ameliyat Masası Başına Düşen Ameliyat Sayısı (Günlük) (ABC Ameliyatlar İçin): Toplam ABC Ameliyat Sayısı/(Aktif Ameliyat Masası Sayısı x 365) | CU6: Cerrahi Hekim Başına Düşen Aylık ABC Ameliyat Sayısı: (Toplam ABC Ameliyat Sayısı x 30 ) / Cerrahi Klinisyen Uzman Sayısı x Belirlenen Süredeki Gün Sayısı) | DJ6: Sezaryen Oranı: Sağlık Tesisinde gerçekleşen tüm doğumların içindeki sezaryen oranını ölçmek için kullanılan sayıdır.(Toplam Sezaryen Yapılan Hasta Sayısı) / Toplam Doğum Sayısı | DL6: Primer Sezaryen oranı: Sağlık Tesisinde gerçekleşen tüm doğumların (mükerrer sezaryen hariç) içindeki primer sezaryen doğumların oranını ölçmek için kullanılan sayıdır. (Toplam Primer Sezaryen Yapılan Hasta Sayısı) / Toplam Yapılan Doğum Sayısı – Mükerrer Sezaryen Yapılan Hasta Sayısı) | DN6: Mesai Dışı Primer Sezaryen Oranı: Mesai Dışı Yapılan Primer Sezaryenlerin Toplam Sezaryen toplam Primer Sezaryen Doğumların içerisindeki oranını gösteren sayıdır. (Mesai Dışı Yapılan Primer Sezaryen Doğum) / (Toplam Primer sezaryen Doğum) | DP6: YOĞUN BAKIM VERİLERİ | DQ6: Yatak Doluluk Oranı: Belirtilen zaman dilimi içinde yatakların ne oranda hasta tarafından kullanıldığını göstermektedir. (Yatılan Gün Sayısı x 100) / (Fiili Yatak sayısı x belirtilen zaman dilimindeki takvim günü) şeklinde hesaplanır. | JA6: Palyatif Bakım Tescilli ve Fiili Yatak Doluluk Oranı verileri tarafınızdan istenmişse Yatak Doluluk Oranı Formülüne Göre Yatak Tipine dikkat edilerek hesaplanması gerekmektedir.
C7: Belirtilen ay içinde hastadan veya hastanın sahip olduğu kamu-özel sigortalardan (SGK, yeşil kart ve GSS vb. dâhil) muayene kaydı yapılan her giriş muayene sayısına dâhil edilmelidir. | F7: (TÜİK 2025 Sonu Adrese Dayalı Nüfus Kayıt Sistemi verilerine göre 2.777.677 olarak duyurulmuştur.) | W7: Poliklinik E-reçete Oranı: Poliklinik E- reçete Sayısı/ Toplam Poliklinik Reçete Sayısı | AG7: Yatan hastaların serviste yattığı gün sayıları, formdaki yatılan gün sayıları alanına yazılacak olup, ayrıca kurum içi başka servisten de sevk edilerek gelen hastaların yattığı gün sayısı da yatılan gün sayılarına eklenmelidir. | BX7: Ameliyat verileri yazılırken ameliyat yapılan hasta sayısı değil yapılan ameliyat sayısı dikkate alınmalıdır. Aynı kişiye, aynı genel anestezi altında birden fazla yapılan ve ücrete tabii olan ameliyatların tümü ayrı ayrı formlarda gösterilmelidir. | CC7: Günübirlik ameliyatlara yazılan veriler ayrıca başka yere yazılmamalıdır. Aynı ameliyat hem günübirlik hem de günübirlik olmayan ameliyat kısmına yazılamaz. | DP7: Yoğun Bakım servislerinde verilen hizmetin kapasitesi, mevcut kapasitenin yeterli olup olmadığı ve birim performansının ölçülebilirliğinin sağlanabilmesi için Yoğun Bakım servisinin seviyesine ve uzmanlık dalına göre yatak sayısı, yatırılan hasta sayısı, yatak doluluk oranı, ortalama kalış süresi, ventilatöre bağlanan hasta sayısı ve süresi gibi istatistiklerin yoğun bakım servisi bazında tespit edilmesi ve bakanlığımızca yürütülmekte olan planlamalara ışık tutması bakımından önem arz etmektedir.
C8: Ancak sadece enjeksiyon ve pansuman için gelen hasta kayıtları muayeneye dahil edilmeyecektir. | G8: Kişi Başı Hekime Müracaat Sayısı: Ağız Diş Muayene Sayısı hariç Toplam Muayene Sayısının Nüfusun 1/1000 lik kısmına düşen muayene sayısı olarak hesaplanır. | K8: Acil Yeşil/Sarı/Kırmızı Alan Muayene Oranı: Münferit Yeşil/Sarı/Kırmızı Alan Muayene Sayısı/ Toplam Acil Muayene Sayısı | S8: Dahili Branş Muayene Sayıları: Ek 1’deki listeye göre Dahili Branşlara ait polikliniklerde verilen hizmete dair muayene sayılarını ifade eder. | V8: Poliklinik Oda Sayısı: Fiilen aktif poliklinik odası sayısını ifade eder. Aylık olarak tabloda belirtilmesi gerekmektedir. | W8: Poliklinik Manuel reçete Oranı: Poliklinik Manuel reçete Sayısı/ Toplam Poliklinik Reçete Sayısı | AG8: Örneğin; 5 Ocak‟ta Dahiliye servisine yatışı yapılan bir hasta 8 Ocak‟ta Dahiliye servisinden Üroloji servisine sevk edilip buradan 12 Ocakta taburcu olursa; | BR8: Acil tıp teknikeri | BS8: Biyolog | BX8: Acil servise başvurarak acil uzmanı tarafından ameliyat edilen hastalar, acil servis ameliyatı olarak gösterilmeli; ancak acil serviste başka bir uzmanlık dalından hekim nöbet sırasında hastayı ameliyat etmişse, hekimin bağlı olduğu servisin ameliyatı olarak girilmelidir. | CC8: Diğer Günübirlik (A+B+C) Ameliyat Sayısı: Günübirlik protokolü ile yapılan A, B, C grubu ameliyatlar diğer günübirlik ameliyatlara yazılmalıdır. Bu ameliyat sayısı A, B ve C grubu ameliyat sayısına dahil edilmemelidir. Medula servis yatış protokolüne göre yatırılan hastaların A-B-C grubu ameliyat sayısı bu alana girilmemelidir. | DP8: Yoğun bakım servislerinin taşıması gereken fiziki şartlar, tıbbi donanım ve personel standartları, yoğun bakım yataklarının basamaklandırılması, nöbet esasları ve hizmetin işleyişine ilişkin usul ve esaslar ( güncellemeler de göz önüne bulundurularak) resmi gazetede yayınlanan Bakanlığımız tebliği dikkate alarak doldurulacaktır. | DQ8: Ventilatör Kulanım Oranı: Ventilatör Gün Sayısı / Yatılan Gün Sayısı
C9: Kontrol muayeneleri için ayrı bir protokol kaydı açılmadığı sürece muayene sayısına dâhil edilmeyecektir. Ayrı bir protokol kaydı açılarak kontrol muayenesine gelen hasta verisi muayene sayısına dâhil edilecektir. | G9: [Toplam Muayene Sayısı (Acil+Pol) x 1000] / TÜİK’in resmi olarak son açıklanan Antalya Nüfusu | S9: Cerrahi Branş Muayene Sayıları: Ek 1’deki listeye göre Cerrahi Branşlara ait polikliniklerde verilen hizmete dair muayene sayılarını ifade eder. | W9: Acil E-reçete Oranı: Acil E- reçete Sayısı/ Toplam Acil Reçete Sayısı | AG9: Dahiliye servisi | BR9: Acil tıp teknisyeni | BS9: Biyomedikal cihaz teknikeri | BX9: Sezeryan ameliyatı olan hasta sayıları, Kadın Hast. ve Doğum branşında ilgili ameliyat grubunda gösterilecektir. | CC9: Toplam ABC ameliyat sayısı: | DP9: Bu nedenle; Yoğun Bakım başlığı altında yer alan yoğun bakım verilerinin doğru, güvenilir ve eksiksiz olarak doldurulması gerekmektedir.
C10: Radyoloji ve Nükleer Tıp servislerinde muayene yapılmaz, bu servislerde verilmiş olan hizmet tetkik kısmında gösterilmelidir. | W10: Acil Manuel reçete Oranı: Acil Manuel reçete Sayısı/ Toplam Acil Reçete Sayısı | AG10: Yatan Hasta Sayısı | AH10: 1 | BR10: Adli tıp teknikeri | BS10: Çevre sağlığı teknikeri | BX10: Ameliyatı yapılacak hastaların yatış türü günübirlik ya da normal yatış olarak yapılabilmektedir. Ameliyat sayısı girilirken bu hususa dikkat edilmelidir. | CC10: (A + B +C + Diğer Günübirlik (A+B+C) Ameliyat Olan Toplam Hasta Sayısı:) | DP10: Yoğun bakım yataklarını, Bakanlıkça tescil edilmiş basamak (1. basamak, 2. basamak ve 3. basamak) ve o basamaktaki yatak sayısını esas alarak giriniz. Henüz tescil işlemi tamamlanmamış yoğun bakımlar için (tescil işlemleri tamamlanana kadar) varsayılan basamak ve o basamaktaki mevcut yatak sayısı girilecektir. Yoğun bakım yatak sayıları, ayrıca ilgili servise yazılmamalıdır. Yoğun bakım yatak sayısını forma girerken, yatak hangi basamağa girilmiş ise, diğer sütunlarda istenen; ventilatör sayısı, yatılan gün sayısı, yatan hasta sayısı ve benzeri veriler de yoğun bakım yatak sayısının ait olduğu basamağa girilecektir. | DQ10: Ventilatör Doluluk oranı: (Ventilatör Gün Sayısı x 100) / (Ventilatör sayısı x belirtilen zaman dilimindeki takvim günü)
C11: Nükleer Tıp branşına ait sadece “radyoaktif iyot tedavisi muayenesi” muayenes sayısına dahil edilmelidir. | S11: CERRAHİ KLİNİSYEN BRANŞLARIN LİSTESİ | AG11: Yatılan Gün Sayısı | AH11: 3 | BR11: Ağız ve diş sağlığı teknikeri | BS11: Çevre sağlığı teknisyeni | BX11: A, B, C, D, E grubu ameliyat verilerine normal yatışı yapılan (En az 1 gece) hastanın ameliyat sayısı yazılmalıdır. Normal yatış ile yapılan A, B, C, D, E grubu ameliyat sayısı sadece A, B, C, D, E grubu ameliyat sayısı alanında yazılacak olup ayrıca günübirlik ameliyat içinde gösterilmemelidir. | CC11: A, B, C, Diğer Günübirlik (A Günübirlik, B Günübirlik ve C Günübirlik) grubundaki ameliyat olan hasta sayısının toplamı girilmelidir. Hasta aynı anestezi altında birden fazla ameliyat geçirmiş ise en büyük olan ameliyat grubunda sayılmalıdır. Ameliyat olan hasta sayısı alınırken; • Hasta aynı anestezi altında birden fazla ameliyat geçirmiş ise ameliyat olan hasta sayısı 1 (bir) olarak alınmalıdır.
S12: 1. Ağız Yüz ve Çene Cerrahisi | AG12: Üroloji servisi | BR12: Ameliyathane teknikeri | BS12: Çocuk gelişimcisi | CC12: Örneğin; D grubunda günübirlik yapılan bir ameliyat, D günübirlik ameliyat grubuna yazılmalı, D grubu ameliyat alanına yazılmamalıdır. | DP12: Örnek 1: Sadece 1. basamak yoğun bakım yatağı var ise ventilatör sayısı, yatan hasta sayısı, yatılan gün sayısı gibi diğer veriler de 1. Basamağa girilecektir. 2. ve 3. Basamağa ait sütunlara “0” yazılmalıdır. | DQ12: Yoğun Bakım Yatak Doluluk oranı: her basamak için ayrı olarak (Yatılan Gün Sayısı x 100) / (Yatak sayısı x belirtilen zaman dilimindeki takvim günü)
C13: Genel Toplam Muayene Sayısı (ACİL+POL+DİŞ+TÜMÜ): Kılavuzda hariç edilmesi belirtilen girişler hariç (enjeksiyon, kontrol muay. Radyoloji vb.) tüm muayenelerin sayısını ifade eder. | AG13: Yatan Hasta Sayısı | AH13: 0 | BR13: Anestezi teknikeri | BS13: Evde hasta bakım teknikeri | CC13: USG, EKO, EMG, EKG, gasroskopi, kolonoskopi, bronskoskopi, sistoskopi, artroskopi, anjiyogrofi cihazları ile yapılan işlemler diğer tıbbi cihazlar sayfasındaki ilgili tetkik sayıları kısmına yazılmalıdır. Ayrıca laparoskopi, artroskopi, faco vb. gibi cihazlar ile yapılan işlemlerden girişimsel İşlemler ameliyat grup karşılığı olanlar ilgili branşın, ilgili ameliyat grubuna eklenecektir | DP13: Örnek 2: Yoğun bakım yatağı 2. ve 3. Basmakta ise diğer sütunlarda istenen bilgiler de 2. ve 3. Basamağa girilir. 1. Basmak verilerine “0” yazılmalıdır.
S14: 2. Beyin ve Sinir Cerrahisi | AG14: Yatılan Gün Sayısı | AH14: 4 | BR14: Anestezi teknisyeni | BS14: Psikolog | CC14: Veri alanlarına girilecek verisi olmayan kurumlar, bu alanlara “0” (sıfır) girmelidirler. | DP14: Hastane veri seti formunda her yoğun bakım basamağı için ayrı ayrı olmak üzere; yatak sayısı, yatan hasta sayısı, yatılan gün sayısı, yatak doluluk oranı, ventilatör sayısı, ventilatöre bağlı kalınan gün sayısı, ventilatör kullanım oranı verileri girilmesi gerekmektedir.
BR15: Dil ve konuşma terapisti | BS15: Sağlık eğitimcisi | DP15: İlgili bölümde veri mevcut olmaması halinde boş bırakılmamalı bu alanlara “0” yazılmalıdır.
S16: 3. Çocuk Cerrahisi | AG16: Taburcu Olan; hastaların şifa ile haliyle, kendi isteği ile hastaneden ayrılan veya başka hastanelere sevk edilen hastaların toplamı yazılacaktır. Hastane içinde başka servise gönderilen hastalar bu alana yazılmayacaktır. | BR16: Diş protez teknikeri | BS16: Sağlık idarecisi | DP16: Yoğun bakım yatan hasta sayısı ve yatılan gün sayısı gibi veriler; hastanın sağlık durumunun gerektirdiği şekilde, hastanın hangi basmamak yoğun bakım ihtiyacı olduğu ve yatışının yapıldığına göre değil, hastanın fiilen yatmakta olduğu yoğun bakım yatağının tescilinin hangi basamak olduğuna göre hesaplanmalıdır.
AG17: Örneğin; Dahiliye kliniğinde yatarken kardiyoloji kliniğine sevk edilen hasta kardiyoloji kliniğinden sonra hastaneden taburcu olursa; bu hasta Dahiliye kliniği taburcu sayısına eklenmemeli, sadece Kardiyoloji kliniği taburcu sayısına eklenmelidir. | BR17: Diş tabibi ve uzman diş tabibi | BS17: Sosyal çalışmacı | DP17: Servisten Gelip Yoğun Bakımda Yatan Hasta Sayısı; geldiği servisin yatan hastası olarak kayıt altına alındığından, bu alandaki hastalar Hastaneniz toplam yatan hasta sayısına mükerrer dâhil edilmemelidir.
S18: 4. Genel Cerrahi | AG18: Yatılan Gün Sayısı; yatan hastaların hastanede kaldığı günlerin toplamıdır. Yatılan gün sayısına, hastanede veri girilen dönem içinde, taburcu olan, ölen, yatarken başka servise giden ve halen yatan hastaların yatılan günlerinin toplamı yazılmalıdır. Kısacası belirtilen dönem içinde ilgili serviste yatmış olan ve halen yatan tüm hastaların yattığı gün sayısı hesaba katılmalıdır. Bu alana yatışı yapılan hastaların yatılan günü alınacak olup, günübirlik hastaların yatış saatleri bu alana dâhil edilmeyecektir. Aynı gün yatışı yapılan (günübirlik hariç) bir hasta, aynı gün içerisinde taburcu edilirse; yatılan günü “1” olarak alınacaktır. | BR18: Diyaliz teknikeri | BS18: Sosyal hizmet uzmanı | DP18: Aynı zamanda servisten yoğun bakıma giden hasta, servisteki taburcu alanında kesinlikle gösterilmemelidir.
AG19: Örneğin; 20 Haziran 2014‟de Dahiliye kliniğine yatan ve 10 Temmuz 2014 itibariyle de Dahiliye kliniğinde yatmaya devam eden hasta için, yatılan gün sayısının 11 gününü Haziran 2013 tarihinde 9 gününü ise Temmuz 2013 tarihinde göstermesi gerekmektedir. | BR19: Diyetisyen | BS19: Tıbbi sekreter | DP19: Yoğun Bakıma Direkt Yatan Hasta Sayısı (Servisten Gelmeden); basamaklarına göre girilmelidir. Yoğun bakımdaki bu alana yazılan yatan hasta sayısı direkt yoğun bakım servisine yatırıldığından hastanenizin toplam yatan hasta sayısı dâhil edilmelidir.
S20: 5. Göğüs Cerrahisi | AG20: Yatılan gün hesaplanmasında hastanın giriş çıkış günlerinden yalnız girdiği gün sayılır çıkış günü sayılmaz, hastanın çıkış tarihinden giriş tarihi çıkarılarak elde edilir. Aynı gün yatıp çıkan hastanın hasta günü “1” gün olarak kabul edilir. | BR20: Ebe | BS20: Tıbbi teknolog | DP20: Ayrıca, diğer kurumlardan sevk edilen hastalar başka servise yatışı yapılmadan direkt yoğun bakım servisine yatırıldı ise bu hastalar da “Yoğun Bakıma Direk Yatan Hasta Sayısı” alanına dâhil edilmelidir.
AG21: Bir servisin belirtilen dönem içindeki yatan hasta sayısı hesaplanırken, o servisteki “yatan hasta sayısı”na; “başka serviste yatarken taburcu olmadan bu servise gelip yatan hasta sayısı” dahil edilerek yazılmalıdır. | BR21: Ebe yardımcısı | BS21: Yaşlı bakım teknikeri | DP21: Yoğun Bakımdan Servise Çıkan Hasta Sayısı; yoğun bakım servisinde tedavisi tamamlanarak servise gönderilen hastalara ait veriler hastanenizin toplam taburcu sayısına dâhil edilmemelidir. Ancak Yoğun bakım hizmet raporunda, yoğun bakım hasta kalış sürelerinin doğru hesaplanabilmesi için bu alan yoğun bakım çıkan hastasına dâhil edilmelidir.
S22: 6. Göz Hastalıkları | AG22: Eğer bir Ana Dal veya Yan Dal‟ın yoğun bakım servisi varsa, bu serviste yapılan işlemler SADECE yoğun bakıma YAZILMALIDIR. | BR22: Eczacı | DP22: Yoğun Bakımdan Direkt Taburcu Olan Hasta Sayısı; yoğun bakım servisinden diğer servislere gitmeden, direk taburcu olan hasta sayısı bu alana eklenmelidir. Ayrıca Yoğun bakımdan sevk edilen hastalar da hem Yoğun bakım verileri hesaplanırken yoğun bakımdan çıkan hasta sayısında hem de hastaneniz genel verileri hesaplanırken hastanenizin toplam taburcu sayısına mükerrer olmamak suretiyle hesaplamalara dâhil edilmelidir.
AG23: Yoğun bakım yatak, yatılan gün, ölen hasta ve taburcu sayıları ilgili servislere eklenmemelidir. | BR23: Eczane Teknikeri | DP23: Yoğun Bakımda Ölen Hasta Sayısı; bu alana, sadece yoğun bakımda ölen hasta sayısı girilmelidir. Yoğun bakımda ölen hasta sayıları ayrıca ilgili servise yazılmamalıdır.
S24: 7. Kadın Hastalıkları ve Doğum | AG24: Servisten yoğun bakıma giden veyahut yoğun bakımdan bir üst seviye yoğun bakıma giden hasta, servisteki veya ilk yoğun bakım seviyesindeki taburcu alanında kesinlikle gösterilmemelidir. | BR24: Elektronörofizyoloji Teknikeri
BR25: Fizyoterapi teknikeri | DP25: Yoğun Bakımdan Diğer Kurumlara Sevk Edilen Hasta Sayısı; ilgili yoğun bakımın taburcu sayısına, dolayısıyla da hastaneniz genel taburcu sayısına mükerrer olmamak suretiyle eklenmelidir.
S26: 8. Kalp Damar Cerrahisi | BR26: Fizyoterapist | DP26: Diğer Kurumlardan Direkt Olarak Yoğun Bakıma Alınan Hasta Sayısı; Bu hastaların ayrıca seviyelerine göre ilgili yoğun bakımın “yoğun bakıma yatan hasta sayısı “ ve dolayısıyla “hastaneniz toplam yatan hasta sayısı” alanlarına da dâhil edilmesi gerekmektedir.
BR27: Hemşire | DP27: Yoğun Bakım Yatılan Gün Sayısı; veri girilen dönem içinde, hangi nedenle olursa olsun yoğun bakımdan çıkan (servise çıkan, taburcu olan, başka kuruma sevk edilen, başka kurumdan gelip yatan, ölen) ve halen yatan hastaların yatılan günlerinin toplamı yazılmalıdır.
S28: 9. Kulak Burun Boğaz Hastalıkları | BR28: Hemşire yardımcısı | DP28: Örneğin; 5 Haziran 2014 de yoğun bakıma yatan ve 30 Haziran 2014 itibariyle de yoğun bakımda yatmaya devam eden hasta için, yatılan gün sayısına 26 (30-5+1) eklenmelidir. Eğer bu hasta 30 Haziranda 2014 tarihinde taburcu oldu ise, yatılan gün sayısına, 25 (30-5) eklenmelidir. (Hasta Taburcu olduğundan, taburcu olduğu gün sayılmamalıdır.)
BR29: İş ve uğraşı teknikeri (Ergoterapi teknikeri) | DP29: Bir hasta için yoğun bakım servisinde, basamaklar veya diğer yoğun bakımlar arasında geçiş yapılmış ise, her basamağın veya geçiş yapıldığı ilgili yoğun bakıma ait veriler ayrı ayrı girilecektir.
S30: 10. Ortopedi ve Travmatoloji | BR30: İş ve uğraşı terapisti (Ergoterapist) | DP30: Örnek 1: Bir hasta 3. basamak yoğun bakımda 5 gün yatarken, 1. basamak yoğun bakıma transfer edilerek 3 gün de bu basamakta yatırılıp normal kliniğe çıkışı yapılmış ise form üzerinde uygulanacak işlem şu şekildedir; 3. basamak sütununda 5 günlük veri ait olduğu sütuna girilir, 1.basamağa ait 3 günlük veri ise ayrı olarak ait olduğu basmaktaki sütuna girilir.
BR31: Klinik psikolog | DP31: Veri alanlarına girilecek verisi olmayan kurumlar, bu alanlara “0” (sıfır) girmelidirler.
S32: 11. Plastik, Rekonstrüktif ve Estetik Cerrahi | BR32: Mamografi teknikeri
BR33: Odyolog | DP33: YOĞUN BAKIM DİĞER DONANIMLAR
S34: 12. Üroloji | BR34: Odyometri teknikeri | DP34: Yoğun Bakımda Kullanılan Diyaliz Cihaz Sayısı: Sadece yoğun bakım servisinde kullanılan diyaliz cihazları girilmelidir.
BR35: Optisyen | DP35: Yoğun Bakımda Bulunan Transport Ventilatör Sayısı: Bu alana yoğun bakımlarda düzenli olarak kullanılan transport ventilatörlerin tamamı yazılmalıdır.
S36: 13. Periferik Damar Cerrahisi | BR36: Perfüzyonist | DP36: Yoğun Bakımda Bulunan Mekanik Ventilatör Sayısı: Bu alana yoğun bakımda bulunan mekanik ventilatörler (HEK ayrılmamış ya da HEK işlemi başlatılmamış ventilatörler )girilecek olup arızalı olan ventilatörler de dahil edilmelidir. Bu alana sadece ventilatörler girilecek olup anestezi cihazları dahil edilmemelidir.
BR37: Podolog | DP37: Ventilatöre Bağlanan Hasta Sayısı; bu alana Yoğun bakımda yatarken ventilatöre bağlanan hastaların sayısı yazılmalıdır.
S38: 14. El Cerrahisi | BR38: Radyoterapi teknikeri | DP38: Ventilatöre Bağlı Kalınan Gün Sayısı; bu alana hastanın yoğun bakımda ventilatöre bağlı kaldığı günlerin toplamı yazılmalıdır. Ventilatöre bağlanan bir hasta gün içinde belirli bir süre veya aralıklı olarak kaç saat bağlı kalırsa kalsın 1 gün olarak yazılacaktır.
BR39: Sağlık bakım teknisyeni | DP39: Örneğin: Bir hasta ventilatöre gün içinde aralıklı olarak ister 1 saat isterse 5 saat bağlanmış olsun, bu sütuna 1 gün şeklinde girilecektir.
S40: 15. Gastroenteroloji Cerrahisi | BR40: Sağlık fizikçisi
BR41: Tabip ve uzman tabip
S42: 16. Perinatoloji | BR42: Tıbbi görüntüleme teknikeri
...

Sheet Veri
A3: DÖNEM | B3: 2026-01
A4: Dönem Gün Sayısı | B4: 31
A6: Dah Ser.Yatılan Gün Sayısı
A7: Cer. Ser.Yatılan Gün Sayısı
